Exception in thread Thread-56:
Traceback (most recent call last):
  File "/usr/local/lib/python3.7/site-packages/urllib3/connection.py", line 171, in _new_conn
    (self._dns_host, self.port), self.timeout, **extra_kw)
  File "/usr/local/lib/python3.7/site-packages/urllib3/util/connection.py", line 56, in create_connection
    for res in socket.getaddrinfo(host, port, family, socket.SOCK_STREAM):
  File "/usr/local/lib/python3.7/socket.py", line 748, in getaddrinfo
    for res in _socket.getaddrinfo(host, port, family, type, proto, flags):
socket.gaierror: [Errno -3] Temporary failure in name resolution

During handling of the above exception, another exception occurred:

Traceback (most recent call last):
  File "/usr/local/lib/python3.7/site-packages/urllib3/connectionpool.py", line 600, in urlopen
    chunked=chunked)
  File "/usr/local/lib/python3.7/site-packages/urllib3/connectionpool.py", line 343, in _make_request
    self._validate_conn(conn)
  File "/usr/local/lib/python3.7/site-packages/urllib3/connectionpool.py", line 849, in _validate_conn
    conn.connect()
  File "/usr/local/lib/python3.7/site-packages/urllib3/connection.py", line 314, in connect
    conn = self._new_conn()
  File "/usr/local/lib/python3.7/site-packages/urllib3/connection.py", line 180, in _new_conn
    self, "Failed to establish a new connection: %s" % e)
urllib3.exceptions.NewConnectionError: <urllib3.connection.VerifiedHTTPSConnection object at 0x7fe973df7e48>: Failed to establish a new connection: [Errno -3] Temporary failure in name resolution

During handling of the above exception, another exception occurred:

Traceback (most recent call last):
  File "/usr/local/lib/python3.7/site-packages/requests/adapters.py", line 445, in send
    timeout=timeout
  File "/usr/local/lib/python3.7/site-packages/urllib3/connectionpool.py", line 638, in urlopen
    _stacktrace=sys.exc_info()[2])
  File "/usr/local/lib/python3.7/site-packages/urllib3/util/retry.py", line 398, in increment
    raise MaxRetryError(_pool, url, error or ResponseError(cause))
urllib3.exceptions.MaxRetryError: HTTPSConnectionPool(host='twitter.com', port=443): Max retries exceeded with url: /search?f=tweets&q=https%3A%2F%2Fwww.sondakikaturk.com.tr%2Fasayis%2Fdansozun-gogsune-para-sikistiran-kocasini-bicakladi-esinin-h122030.html%3Futm_source%3Ddlvr.it%26utm_medium%3Dtwitter%20since%3A2006-03-01%20until%3A2012-08-29&src=typd (Caused by NewConnectionError('<urllib3.connection.VerifiedHTTPSConnection object at 0x7fe973df7e48>: Failed to establish a new connection: [Errno -3] Temporary failure in name resolution'))

During handling of the above exception, another exception occurred:

Traceback (most recent call last):
  File "/usr/local/lib/python3.7/threading.py", line 917, in _bootstrap_inner
    self.run()
  File "/usr/local/lib/python3.7/threading.py", line 865, in run
    self._target(*self._args, **self._kwargs)
  File "/usr/src/app/core.py", line 80, in call
    displayArray=kwargs['displayArray'])
  File "/usr/src/app/modules/cdGetTwitter.py", line 105, in getTwitter
    datetime.datetime.now(), verbose)
  File "/usr/src/app/modules/cdGetTwitter.py", line 75, in getEarliestDate
    result = getDates(uri, from_date, midDate, verbose)
  File "/usr/src/app/modules/cdGetTwitter.py", line 44, in getDates
    response = requests.get(search_str, headers=headers)
  File "/usr/local/lib/python3.7/site-packages/requests/api.py", line 72, in get
    return request('get', url, params=params, **kwargs)
  File "/usr/local/lib/python3.7/site-packages/requests/api.py", line 58, in request
    return session.request(method=method, url=url, **kwargs)
  File "/usr/local/lib/python3.7/site-packages/requests/sessions.py", line 512, in request
    resp = self.send(prep, **send_kwargs)
  File "/usr/local/lib/python3.7/site-packages/requests/sessions.py", line 622, in send
    r = adapter.send(request, **kwargs)
  File "/usr/local/lib/python3.7/site-packages/requests/adapters.py", line 513, in send
    raise ConnectionError(e, request=request)
requests.exceptions.ConnectionError: HTTPSConnectionPool(host='twitter.com', port=443): Max retries exceeded with url: /search?f=tweets&q=https%3A%2F%2Fwww.sondakikaturk.com.tr%2Fasayis%2Fdansozun-gogsune-para-sikistiran-kocasini-bicakladi-esinin-h122030.html%3Futm_source%3Ddlvr.it%26utm_medium%3Dtwitter%20since%3A2006-03-01%20until%3A2012-08-29&src=typd (Caused by NewConnectionError('<urllib3.connection.VerifiedHTTPSConnection object at 0x7fe973df7e48>: Failed to establish a new connection: [Errno -3] Temporary failure in name resolution'))

{
    "self": "",
    "uri": "https://www.sondakikaturk.com.tr/asayis/dansozun-gogsune-para-sikistiran-kocasini-bicakladi-esinin-h122030.html?utm_source=dlvr.it&utm_medium=twitter",
    "estimated-creation-date": "",
    "earliest-sources": [],
    "sources": {
        "bing.com": {
            "earliest": ""
        },
        "google.com": {
            "earliest": ""
        },
        "twitter.com": {
            "earliest": ""
        },
        "bitly.com": {
            "earliest": ""
        },
        "last-modified": {
            "earliest": ""
        },
        "pubdate": {
            "earliest": ""
        },
        "backlinks": {
            "earliest": ""
        }
    }
}
